[2023-07-08T15:43:05.170+0000] {taskinstance.py:1103} INFO - Dependencies all met for dep_context=non-requeueable deps ti=<TaskInstance: csv_to_postgres_dag2.insert_data_to_postgres scheduled__2023-01-08T00:00:00+00:00 [queued]>
[2023-07-08T15:43:05.187+0000] {taskinstance.py:1103} INFO - Dependencies all met for dep_context=requeueable deps ti=<TaskInstance: csv_to_postgres_dag2.insert_data_to_postgres scheduled__2023-01-08T00:00:00+00:00 [queued]>
[2023-07-08T15:43:05.188+0000] {taskinstance.py:1308} INFO - Starting attempt 1 of 2
[2023-07-08T15:43:05.209+0000] {taskinstance.py:1327} INFO - Executing <Task(PythonOperator): insert_data_to_postgres> on 2023-01-08 00:00:00+00:00
[2023-07-08T15:43:05.217+0000] {standard_task_runner.py:57} INFO - Started process 237 to run task
[2023-07-08T15:43:05.221+0000] {standard_task_runner.py:84} INFO - Running: ['***', 'tasks', 'run', 'csv_to_postgres_dag2', 'insert_data_to_postgres', 'scheduled__2023-01-08T00:00:00+00:00', '--job-id', '178', '--raw', '--subdir', 'DAGS_FOLDER/etl.py', '--cfg-path', '/tmp/tmpcnxodovv']
[2023-07-08T15:43:05.225+0000] {standard_task_runner.py:85} INFO - Job 178: Subtask insert_data_to_postgres
[2023-07-08T15:43:05.312+0000] {task_command.py:410} INFO - Running <TaskInstance: csv_to_postgres_dag2.insert_data_to_postgres scheduled__2023-01-08T00:00:00+00:00 [running]> on host 9aa32a2a42d2
[2023-07-08T15:43:05.436+0000] {taskinstance.py:1547} INFO - Exporting env vars: AIRFLOW_CTX_DAG_OWNER='***' AIRFLOW_CTX_DAG_ID='csv_to_postgres_dag2' AIRFLOW_CTX_TASK_ID='insert_data_to_postgres' AIRFLOW_CTX_EXECUTION_DATE='2023-01-08T00:00:00+00:00' AIRFLOW_CTX_TRY_NUMBER='1' AIRFLOW_CTX_DAG_RUN_ID='scheduled__2023-01-08T00:00:00+00:00'
[2023-07-08T15:43:05.632+0000] {taskinstance.py:1824} ERROR - Task failed with exception
Traceback (most recent call last):
  File "/home/airflow/.local/lib/python3.7/site-packages/airflow/operators/python.py", line 181, in execute
    return_value = self.execute_callable()
  File "/home/airflow/.local/lib/python3.7/site-packages/airflow/operators/python.py", line 198, in execute_callable
    return self.python_callable(*self.op_args, **self.op_kwargs)
  File "/opt/airflow/dags/etl.py", line 66, in insert_data_to_postgres
    modified_df.to_sql('reviews', con='postgres_airflow', if_exists='append', index=False)
  File "/home/airflow/.local/lib/python3.7/site-packages/pandas/core/generic.py", line 2882, in to_sql
    method=method,
  File "/home/airflow/.local/lib/python3.7/site-packages/pandas/io/sql.py", line 708, in to_sql
    pandas_sql = pandasSQL_builder(con, schema=schema)
  File "/home/airflow/.local/lib/python3.7/site-packages/pandas/io/sql.py", line 786, in pandasSQL_builder
    con = _engine_builder(con)
  File "/home/airflow/.local/lib/python3.7/site-packages/pandas/io/sql.py", line 771, in _engine_builder
    con = sqlalchemy.create_engine(con)
  File "<string>", line 2, in create_engine
  File "/home/airflow/.local/lib/python3.7/site-packages/sqlalchemy/util/deprecations.py", line 375, in warned
    return fn(*args, **kwargs)
  File "/home/airflow/.local/lib/python3.7/site-packages/sqlalchemy/engine/create.py", line 514, in create_engine
    u = _url.make_url(url)
  File "/home/airflow/.local/lib/python3.7/site-packages/sqlalchemy/engine/url.py", line 738, in make_url
    return _parse_url(name_or_url)
  File "/home/airflow/.local/lib/python3.7/site-packages/sqlalchemy/engine/url.py", line 800, in _parse_url
    "Could not parse SQLAlchemy URL from string '%s'" % name
sqlalchemy.exc.ArgumentError: Could not parse SQLAlchemy URL from string 'postgres_***'
[2023-07-08T15:43:05.654+0000] {taskinstance.py:1350} INFO - Marking task as UP_FOR_RETRY. dag_id=csv_to_postgres_dag2, task_id=insert_data_to_postgres, execution_date=20230108T000000, start_date=20230708T154305, end_date=20230708T154305
[2023-07-08T15:43:05.670+0000] {standard_task_runner.py:109} ERROR - Failed to execute job 178 for task insert_data_to_postgres (Could not parse SQLAlchemy URL from string 'postgres_***'; 237)
[2023-07-08T15:43:05.716+0000] {local_task_job_runner.py:225} INFO - Task exited with return code 1
[2023-07-08T15:43:05.753+0000] {taskinstance.py:2653} INFO - 0 downstream tasks scheduled from follow-on schedule check
