[2023-07-08T15:34:46.716+0000] {taskinstance.py:1103} INFO - Dependencies all met for dep_context=non-requeueable deps ti=<TaskInstance: csv_to_postgres_dag2.create_postgres_table manual__2023-07-08T15:34:44.139865+00:00 [queued]>
[2023-07-08T15:34:46.735+0000] {taskinstance.py:1103} INFO - Dependencies all met for dep_context=requeueable deps ti=<TaskInstance: csv_to_postgres_dag2.create_postgres_table manual__2023-07-08T15:34:44.139865+00:00 [queued]>
[2023-07-08T15:34:46.736+0000] {taskinstance.py:1308} INFO - Starting attempt 1 of 2
[2023-07-08T15:34:46.762+0000] {taskinstance.py:1327} INFO - Executing <Task(PostgresOperator): create_postgres_table> on 2023-07-08 15:34:44.139865+00:00
[2023-07-08T15:34:46.771+0000] {standard_task_runner.py:57} INFO - Started process 110 to run task
[2023-07-08T15:34:46.777+0000] {standard_task_runner.py:84} INFO - Running: ['***', 'tasks', 'run', 'csv_to_postgres_dag2', 'create_postgres_table', 'manual__2023-07-08T15:34:44.139865+00:00', '--job-id', '87', '--raw', '--subdir', 'DAGS_FOLDER/etl.py', '--cfg-path', '/tmp/tmpvuo45p0s']
[2023-07-08T15:34:46.782+0000] {standard_task_runner.py:85} INFO - Job 87: Subtask create_postgres_table
[2023-07-08T15:34:46.865+0000] {task_command.py:410} INFO - Running <TaskInstance: csv_to_postgres_dag2.create_postgres_table manual__2023-07-08T15:34:44.139865+00:00 [running]> on host 9aa32a2a42d2
[2023-07-08T15:34:46.999+0000] {taskinstance.py:1547} INFO - Exporting env vars: AIRFLOW_CTX_DAG_OWNER='***' AIRFLOW_CTX_DAG_ID='csv_to_postgres_dag2' AIRFLOW_CTX_TASK_ID='create_postgres_table' AIRFLOW_CTX_EXECUTION_DATE='2023-07-08T15:34:44.139865+00:00' AIRFLOW_CTX_TRY_NUMBER='1' AIRFLOW_CTX_DAG_RUN_ID='manual__2023-07-08T15:34:44.139865+00:00'
[2023-07-08T15:34:47.001+0000] {sql.py:265} INFO - Executing: 
CREATE TABLE reviews (
    reviewer_id INTEGER,
    store_name VARCHAR(255),
    category VARCHAR(255),
    store_address VARCHAR(255),
    latitude FLOAT,
    longitude FLOAT,
    rating_count INTEGER,
    review_time VARCHAR(255),
    review TEXT,
    rating VARCHAR(10)
);
[2023-07-08T15:34:47.012+0000] {base.py:73} INFO - Using connection ID 'postgres_***' for task execution.
[2023-07-08T15:34:47.110+0000] {base.py:73} INFO - Using connection ID 'postgres_***' for task execution.
[2023-07-08T15:34:47.120+0000] {sql.py:375} INFO - Running statement: 
CREATE TABLE reviews (
    reviewer_id INTEGER,
    store_name VARCHAR(255),
    category VARCHAR(255),
    store_address VARCHAR(255),
    latitude FLOAT,
    longitude FLOAT,
    rating_count INTEGER,
    review_time VARCHAR(255),
    review TEXT,
    rating VARCHAR(10)
);, parameters: None
[2023-07-08T15:34:47.125+0000] {taskinstance.py:1824} ERROR - Task failed with exception
Traceback (most recent call last):
  File "/home/airflow/.local/lib/python3.7/site-packages/airflow/providers/common/sql/operators/sql.py", line 277, in execute
    **extra_kwargs,
  File "/home/airflow/.local/lib/python3.7/site-packages/airflow/providers/common/sql/hooks/sql.py", line 349, in run
    self._run_command(cur, sql_statement, parameters)
  File "/home/airflow/.local/lib/python3.7/site-packages/airflow/providers/common/sql/hooks/sql.py", line 380, in _run_command
    cur.execute(sql_statement)
psycopg2.errors.DuplicateTable: relation "reviews" already exists

[2023-07-08T15:34:47.144+0000] {taskinstance.py:1350} INFO - Marking task as UP_FOR_RETRY. dag_id=csv_to_postgres_dag2, task_id=create_postgres_table, execution_date=20230708T153444, start_date=20230708T153446, end_date=20230708T153447
[2023-07-08T15:34:47.163+0000] {standard_task_runner.py:109} ERROR - Failed to execute job 87 for task create_postgres_table (relation "reviews" already exists
; 110)
[2023-07-08T15:34:47.189+0000] {local_task_job_runner.py:225} INFO - Task exited with return code 1
[2023-07-08T15:34:47.237+0000] {taskinstance.py:2653} INFO - 0 downstream tasks scheduled from follow-on schedule check
