[2023-07-08T15:43:02.646+0000] {taskinstance.py:1103} INFO - Dependencies all met for dep_context=non-requeueable deps ti=<TaskInstance: csv_to_postgres_dag2.create_postgres_table manual__2023-07-08T15:42:57.696976+00:00 [queued]>
[2023-07-08T15:43:02.664+0000] {taskinstance.py:1103} INFO - Dependencies all met for dep_context=requeueable deps ti=<TaskInstance: csv_to_postgres_dag2.create_postgres_table manual__2023-07-08T15:42:57.696976+00:00 [queued]>
[2023-07-08T15:43:02.665+0000] {taskinstance.py:1308} INFO - Starting attempt 1 of 2
[2023-07-08T15:43:02.691+0000] {taskinstance.py:1327} INFO - Executing <Task(PostgresOperator): create_postgres_table> on 2023-07-08 15:42:57.696976+00:00
[2023-07-08T15:43:02.700+0000] {standard_task_runner.py:57} INFO - Started process 168 to run task
[2023-07-08T15:43:02.704+0000] {standard_task_runner.py:84} INFO - Running: ['***', 'tasks', 'run', 'csv_to_postgres_dag2', 'create_postgres_table', 'manual__2023-07-08T15:42:57.696976+00:00', '--job-id', '152', '--raw', '--subdir', 'DAGS_FOLDER/etl.py', '--cfg-path', '/tmp/tmpfp4yevw9']
[2023-07-08T15:43:02.707+0000] {standard_task_runner.py:85} INFO - Job 152: Subtask create_postgres_table
[2023-07-08T15:43:02.806+0000] {task_command.py:410} INFO - Running <TaskInstance: csv_to_postgres_dag2.create_postgres_table manual__2023-07-08T15:42:57.696976+00:00 [running]> on host 9aa32a2a42d2
[2023-07-08T15:43:02.961+0000] {taskinstance.py:1547} INFO - Exporting env vars: AIRFLOW_CTX_DAG_OWNER='***' AIRFLOW_CTX_DAG_ID='csv_to_postgres_dag2' AIRFLOW_CTX_TASK_ID='create_postgres_table' AIRFLOW_CTX_EXECUTION_DATE='2023-07-08T15:42:57.696976+00:00' AIRFLOW_CTX_TRY_NUMBER='1' AIRFLOW_CTX_DAG_RUN_ID='manual__2023-07-08T15:42:57.696976+00:00'
[2023-07-08T15:43:02.965+0000] {sql.py:265} INFO - Executing: 
CREATE TABLE reviews (
    reviewer_id INTEGER,
    store_name VARCHAR(255),
    category VARCHAR(255),
    store_address VARCHAR(255),
    latitude FLOAT,
    longitude FLOAT,
    rating_count INTEGER,
    review_time VARCHAR(255),
    review TEXT,
    rating VARCHAR(10)
);
[2023-07-08T15:43:02.979+0000] {base.py:73} INFO - Using connection ID 'postgres_***' for task execution.
[2023-07-08T15:43:03.110+0000] {base.py:73} INFO - Using connection ID 'postgres_***' for task execution.
[2023-07-08T15:43:03.117+0000] {sql.py:375} INFO - Running statement: 
CREATE TABLE reviews (
    reviewer_id INTEGER,
    store_name VARCHAR(255),
    category VARCHAR(255),
    store_address VARCHAR(255),
    latitude FLOAT,
    longitude FLOAT,
    rating_count INTEGER,
    review_time VARCHAR(255),
    review TEXT,
    rating VARCHAR(10)
);, parameters: None
[2023-07-08T15:43:03.120+0000] {taskinstance.py:1824} ERROR - Task failed with exception
Traceback (most recent call last):
  File "/home/airflow/.local/lib/python3.7/site-packages/airflow/providers/common/sql/operators/sql.py", line 277, in execute
    **extra_kwargs,
  File "/home/airflow/.local/lib/python3.7/site-packages/airflow/providers/common/sql/hooks/sql.py", line 349, in run
    self._run_command(cur, sql_statement, parameters)
  File "/home/airflow/.local/lib/python3.7/site-packages/airflow/providers/common/sql/hooks/sql.py", line 380, in _run_command
    cur.execute(sql_statement)
psycopg2.errors.DuplicateTable: relation "reviews" already exists

[2023-07-08T15:43:03.143+0000] {taskinstance.py:1350} INFO - Marking task as UP_FOR_RETRY. dag_id=csv_to_postgres_dag2, task_id=create_postgres_table, execution_date=20230708T154257, start_date=20230708T154302, end_date=20230708T154303
[2023-07-08T15:43:03.165+0000] {standard_task_runner.py:109} ERROR - Failed to execute job 152 for task create_postgres_table (relation "reviews" already exists
; 168)
[2023-07-08T15:43:03.199+0000] {local_task_job_runner.py:225} INFO - Task exited with return code 1
[2023-07-08T15:43:03.264+0000] {taskinstance.py:2653} INFO - 0 downstream tasks scheduled from follow-on schedule check
